Workbook

Sheet Uçak sayıları
A1: 13.10.2025 Tarihli YYB Filo bilgisine göre filoda yer alan uçak sayıları | I1: Kişi bazlı inceleme adetleri
A2: Uçak Tipi | B2: Adet | I2: İlgili | J2: A310 | K2: A319 | L2: A320 | M2: A321 | N2: A330 | O2: A350 | P2: B737 | Q2: B747 | R2: B777 | S2: B787 | T2: Beklenen | U2: Toplam | V2: Hedef | W2: Tamamlanan
A3: A310 | B3: 3 | I3: Emre | J3: =COUNTIF('A310'!C:C,"EMRE") -> 0 | K3: =COUNTIF('A319'!C:C,"EMRE") -> 0 | L3: =COUNTIF('A320'!C:C,"EMRE") -> 0 | M3: =COUNTIF('A321'!C:C,"EMRE") -> 0 | N3: =COUNTIF('A330'!C:C,"EMRE") -> 0 | O3: =COUNTIF('A350'!C:C,"EMRE") -> 0 | P3: =COUNTIF('B737'!C:C,"EMRE") -> 0 | Q3: =COUNTIF('B747'!C:C,"EMRE") -> 0 | R3: =COUNTIF('B787'!C:C,"EMRE") -> 0 | S3: =COUNTIF('B787'!C:C,"EMRE") -> 0 | T3: =INT(((TODAY()-B33)/7)*5) -> 35 | U3: =SUM(J3:S3) -> 0 | V3: =IF(U3>=T3,"✔","✖") -> ✖ | W3: =IFERROR(U3/T3,0) -> 0
A4: A319 | B4: 6 | I4: Enis | J4: =COUNTIF('A310'!C:C,"ENİS") -> 0 | K4: =COUNTIF('A319'!C:C,"ENİS") -> 0 | L4: =COUNTIF('A320'!C:C,"ENİS") -> 0 | M4: =COUNTIF('A321'!C:C,"ENİS") -> 5 | N4: =COUNTIF('A330'!C:C,"ENİS") -> 0 | O4: =COUNTIF('A350'!C:C,"ENİS") -> 0 | P4: =COUNTIF('B737'!C:C,"ENİS") -> 6 | Q4: =COUNTIF('B747'!C:C,"ENİS") -> 0 | R4: =COUNTIF('B777'!C:C,"ENİS") -> 0 | S4: =COUNTIF('B787'!C:C,"ENİS") -> 0 | T4: =INT(((TODAY()-B33)/7)*5) -> 35 | U4: =SUM(J4:S4) -> 11 | V4: =IF(U4>=T4,"✔","✖") -> ✖ | W4: =IFERROR(U4/T4,0) -> 0.31428571
A5: A320 | B5: 46 | I5: Umut | J5: =COUNTIF('A310'!C:C,"UMUT") -> 0 | K5: =COUNTIF('A319'!C:C,"UMUT") -> 0 | L5: =COUNTIF('A320'!C:C,"UMUT") -> 0 | M5: =COUNTIF('A321'!C:C,"UMUT") -> 0 | N5: =COUNTIF('A330'!C:C,"UMUT") -> 0 | O5: =COUNTIF('A350'!C:C,"UMUT") -> 0 | P5: =COUNTIF('B737'!C:C,"UMUT") -> 0 | Q5: =COUNTIF('B747'!C:C,"UMUT") -> 0 | R5: =COUNTIF('B777'!C:C,"UMUT") -> 0 | S5: =COUNTIF('B787'!C:C,"UMUT") -> 0 | T5: =INT(((TODAY()-B33)/7)*5) -> 35 | U5: =SUM(J5:S5) -> 0 | V5: =IF(U5>=T5,"✔","✖") -> ✖ | W5: =IFERROR(U5/T5,0) -> 0
A6: A321 | B6: 154 | I6: Taha | J6: =COUNTIF('A310'!C:C,"TAHA") -> 2 | K6: =COUNTIF('A319'!C:C,"TAHA") -> 3 | L6: =COUNTIF('A320'!C:C,"TAHA") -> 10 | M6: =COUNTIF('A321'!C:C,"TAHA") -> 3 | N6: =COUNTIF('A330'!C:C,"TAHA") -> 2 | O6: =COUNTIF('A350'!C:C,"TAHA") -> 3 | P6: =COUNTIF('B737'!C:C,"TAHA") -> 5 | Q6: =COUNTIF('B747'!C:C,"TAHA") -> 3 | R6: =COUNTIF('B777'!C:C,"TAHA") -> 2 | S6: =COUNTIF('B787'!C:C,"TAHA") -> 2 | T6: =INT(((TODAY()-B33)/7)*5) -> 35 | U6: =SUM(J6:S6) -> 35 | V6: =IF(U6>=T6,"✔","✖") -> ✔ | W6: =IFERROR(U6/T6,0) -> 1
A7: A330 | B7: 61 | I7: Tamamlanan | J7: =J3+J4+J5+J6 -> 2 | K7: =K3+K4+K5+K6 -> 3 | L7: =L3+L4+L5+L6 -> 10 | M7: =M3+M4+M5+M6 -> 8 | N7: =N3+N4+N5+N6 -> 2 | O7: =O3+O4+O5+O6 -> 3 | P7: =P3+P4+P5+P6 -> 11 | Q7: =Q3+Q4+Q5+Q6 -> 3 | ... S7: =S3+S4+S5+S6 -> 2
A8: A350 | B8: 30
A9: B737 | B9: 137
A10: B747 | B10: 2
A11: B777 | B11: 42
A12: B787 | B12: 25
A13: Toplam: | B13: =SUM(B3:B12) -> 506 | I13: Boş hücre sayıları
I14: Hücre Tipi | J14: A310 | K14: A319 | L14: A320 | M14: A321 | N14: A330 | O14: A350 | P14: B737 | Q14: B747 | R14: B777 | S14: B787
I15: Toplam Hücre | J15: 2933 | K15: 3464 | L15: 4727 | M15: 4829 | N15: 5093 | O15: 1889 | P15: 5548 | Q15: 1006 | R15: 2933 | S15: 1594
I16: Boş Fonksiyon | J16: =COUNTBLANK('A310'!H2:H2934) -> 2931 | K16: =COUNTBLANK('A319'!H2:H3465) -> 3461 | L16: =COUNTBLANK('A320'!H2:H4728) -> 4717 | M16: =COUNTBLANK('A321'!H2:H4830) -> 4826 | N16: =COUNTBLANK('A330'!H2:H5094) -> 5091 | O16: =COUNTBLANK('A350'!H2:H1890) -> 1886 | P16: =COUNTBLANK('B737'!H2:H5549) -> 5543 | Q16: =COUNTBLANK('B747'!H2:H1007) -> 1003 | R16: =COUNTBLANK('B777'!H2:H2934) -> 2931 | S16: =COUNTBLANK('B787'!H2:H1595) -> 1592
I17: Boş resim | J17: =COUNTBLANK('A310'!J2:J2934) -> 2931 | K17: =COUNTBLANK('A319'!J2:J3465) -> 3461 | L17: =COUNTBLANK('A320'!J2:J4728) -> 4717 | M17: =COUNTBLANK('A321'!J2:J4830) -> 4821 | N17: =COUNTBLANK('A330'!J2:J5094) -> 5091 | O17: =COUNTBLANK('A350'!J2:J1890) -> 1886 | P17: =COUNTBLANK('B737'!J2:J5549) -> 5543 | Q17: =COUNTBLANK('B747'!J2:J1007) -> 1003 | R17: =COUNTBLANK('B777'!J2:J2934) -> 2931 | S17: =COUNTBLANK('B787'!J2:J1595) -> 1592
I18: Tamamlanan | J18: =IFERROR((J15-J16)/J15,0) -> 0.00068189567 | K18: =IFERROR((K15-K16)/K15,0) -> 0.00086605081 | L18: =IFERROR((L15-L16)/L15,0) -> 0.0021155067 | M18: =IFERROR((M15-M16)/M15,0) -> 0.00062124663 | N18: =IFERROR((N15-N16)/N15,0) -> 0.00039269586 | O18: =IFERROR((O15-O16)/O15,0) -> 0.0015881419 | P18: =IFERROR((P15-P16)/P15,0) -> 0.00090122567 | Q18: =IFERROR((Q15-Q16)/Q15,0) -> 0.0029821074 | ... S18: =IFERROR((S15-S16)/S15,0) -> 0.0012547051
A21: Firma bazında uçak sayıları
A22: Turkish Airlines | B22: 361
A23: Ajet | B23: 117
A24: Turkish Cargo | B24: 28
A33: Başlangıç tarihi | B33: 45931

Sheet A310
A1: PID_PN | B1: PN DESC | C1: ilgili | D1: Chapter | E1: Sub Category | F1: QTY | G1: FA Amount | H1: Fonksiyonu | I1: Görsel | J1: Resim Notu
A2: RD-AA8061-11 | B2: (FOR SALE/ 3 RD PARTY) - LAN HUB | D2: 23 | E2: IFE | F2: 3 | G2: 23085.6 | I2: =HYPERLINK("\\avrasya\THY_BSK_TEKNIK\MD_TEKNIK_ANLASMALAR_VE_ODEMELER\Teknik Envanter Takip Şefliği\IPC\A310\" &D2&"\"& A2 & ".png", "Resim için basınız") -> Resim için basınız
A3: 184186-1 | B3: 2 WINDOW TILLER GEARBOX | D3: 56 | E3: MECHANIC | F3: 79 | G3: 4279.1 | I3: =HYPERLINK("\\avrasya\THY_BSK_TEKNIK\MD_TEKNIK_ANLASMALAR_VE_ODEMELER\Teknik Envanter Takip Şefliği\IPC\A310\" &D3&"\"& A3 & ".png", "Resim için basınız") -> Resim için basınız
A4: RD-AA8190-01 | B4: 4G ENHANCED CELL MODEM (4G ECM) | D4: 23 | E4: IFE | F4: 247 | G4: 898253.44 | I4: =HYPERLINK("\\avrasya\THY_BSK_TEKNIK\MD_TEKNIK_ANLASMALAR_VE_ODEMELER\Teknik Envanter Takip Şefliği\IPC\A310\" &D4&"\"& A4 & ".png", "Resim için basınız") -> Resim için basınız
A5: 256W2140-1 | B5: 7,8 SLAT GEARBOX | D5: 27 | E5: MECHANIC | F5: 4 | G5: 38546.82 | I5: =HYPERLINK("\\avrasya\THY_BSK_TEKNIK\MD_TEKNIK_ANLASMALAR_VE_ODEMELER\Teknik Envanter Takip Şefliği\IPC\A310\" &D5&"\"& A5 & ".png", "Resim için basınız") -> Resim için basınız
A6: RD-AA7790-01 | B6: 9-IN VGA MONITOR | D6: 23 | E6: IFE | F6: 2 | G6: 228400.37 | I6: =HYPERLINK("\\avrasya\THY_BSK_TEKNIK\MD_TEKNIK_ANLASMALAR_VE_ODEMELER\Teknik Envanter Takip Şefliği\IPC\A310\" &D6&"\"& A6 & ".png", "Resim için basınız") -> Resim için basınız
A7: 180944-201 | B7: 10.6" IN SEATBACK SVDU | D7: 23 | E7: IFE | F7: 167 | G7: 32505.09 | I7: =HYPERLINK("\\avrasya\THY_BSK_TEKNIK\MD_TEKNIK_ANLASMALAR_VE_ODEMELER\Teknik Envanter Takip Şefliği\IPC\A310\" &D7&"\"& A7 & ".png", "Resim için basınız") -> Resim için basınız
A8: 180199-204 | B8: 10.6" IN-ARM SVDU | D8: 23 | E8: IFE | F8: 17 | G8: 33862.6 | I8: =HYPERLINK("\\avrasya\THY_BSK_TEKNIK\MD_TEKNIK_ANLASMALAR_VE_ODEMELER\Teknik Envanter Takip Şefliği\IPC\A310\" &D8&"\"& A8 & ".png", "Resim için basınız") -> Resim için basınız
A9: RD-FE7805-65 | B9: 10.6" LCD MONITOR | D9: 23 | E9: IFE | F9: 2297 | G9: 30052.47 | I9: =HYPERLINK("\\avrasya\THY_BSK_TEKNIK\MD_TEKNIK_ANLASMALAR_VE_ODEMELER\Teknik Envanter Takip Şefliği\IPC\A310\" &D9&"\"& A9 & ".png", "Resim için basınız") -> Resim için basınız
A10: RD-FE7800-64 | B10: 10.6" SMART MONITOR | D10: 23 | E10: IFE | F10: 9034 | G10: 63162.74 | I10: =HYPERLINK("\\avrasya\THY_BSK_TEKNIK\MD_TEKNIK_ANLASMALAR_VE_ODEMELER\Teknik Envanter Takip Şefliği\IPC\A310\" &D10&"\"& A10 & ".png", "Resim için basınız") -> Resim için basınız
A11: RD-FD6815-51 | B11: 11.1" ECO MONITOR | D11: 23 | E11: IFE | F11: 5997 | G11: 318878.74 | I11: =HYPERLINK("\\avrasya\THY_BSK_TEKNIK\MD_TEKNIK_ANLASMALAR_VE_ODEMELER\Teknik Envanter Takip Şefliği\IPC\A310\" &D11&"\"& A11 & ".png", "Resim için basınız") -> Resim için basınız
A12: RD-FW9715-01 | B12: 15.4? LCD WALL MOUNT | D12: 23 | E12: IFE | F12: 169 | G12: 6484.66 | I12: =HYPERLINK("\\avrasya\THY_BSK_TEKNIK\MD_TEKNIK_ANLASMALAR_VE_ODEMELER\Teknik Envanter Takip Şefliği\IPC\A310\" &D12&"\"& A12 & ".png", "Resim için basınız") -> Resim için basınız
A13: RD-FE9816-01 | B13: 16" WALL MOUNTED MONITOR | D13: 23 | E13: IFE | F13: 262 | G13: 91048.72 | I13: =HYPERLINK("\\avrasya\THY_BSK_TEKNIK\MD_TEKNIK_ANLASMALAR_VE_ODEMELER\Teknik Envanter Takip Şefliği\IPC\A310\" &D13&"\"& A13 & ".png", "Resim için basınız") -> Resim için basınız
... A15: RD-FW9723-01 | B15: 23-IN WALL MOUNT LCD MON | D15: 23 | E15: IFE | F15: 58 | G15: 9935.45 | I15: =HYPERLINK("\\avrasya\THY_BSK_TEKNIK\MD_TEKNIK_ANLASMALAR_VE_ODEMELER\Teknik Envanter Takip Şefliği\IPC\A310\" &D15&"\"& A15 & ".png", "Resim için basınız") -> Resim için basınız
A16: RD-FW7239-01 | B16: 23? LCD MONITOR | C16: TAHA | D16: 23 | E16: IFE | F16: 1 | G16: 17279.03 | H16: Yolculara Uçuş bilgilerini duyuruları ve eğlence içeriklerini sağlayarak kabin içi bilgilendirme ve konforu oluşturur. | I16: =HYPERLINK("\\avrasya\THY_BSK_TEKNIK\MD_TEKNIK_ANLASMALAR_VE_ODEMELER\Teknik Envanter Takip Şefliği\IPC\A310\" &D16&"\"& A16 & ".png", "Resim için basınız") -> Resim için basınız | J16: Resim Girildi
A17: 822-0006-105 | B17: A/P FLIGHT DIREC.COMPUTER | D17: 22 | E17: ATE | F17: 136 | G17: 356872.8 | I17: =HYPERLINK("\\avrasya\THY_BSK_TEKNIK\MD_TEKNIK_ANLASMALAR_VE_ODEMELER\Teknik Envanter Takip Şefliği\IPC\A310\" &D17&"\"& A17 & ".png", "Resim için basınız") -> Resim için basınız
A18: F5746268800400 | B18: A330 SLAT NO 6(LH) | D18: 27 | E18: COMPOSIT | F18: 23 | G18: 0 | I18: =HYPERLINK("\\avrasya\THY_BSK_TEKNIK\MD_TEKNIK_ANLASMALAR_VE_ODEMELER\Teknik Envanter Takip Şefliği\IPC\A310\" &D18&"\"& A18 & ".png", "Resim için basınız") -> Resim için basınız
A19: F5746268800500 | B19: A330 SLAT NO 6(RH) | C19: TAHA | D19: 27 | E19: COMPOSIT | F19: 24 | G19: 0 | H19: Uçus sırasında sağ kanat hücum kenarındaki hava akışını düzenleyerek kaldırmayı artırır ve düşük hızlarda uçağın kontrolünü iyileştirir. | I19: =HYPERLINK("\\avrasya\THY_BSK_TEKNIK\MD_TEKNIK_ANLASMALAR_VE_ODEMELER\Teknik Envanter Takip Şefliği\IPC\A310\" &D19&"\"& A19 & ".png", "Resim için basınız") -> Resim için basınız | J19: Resim Girildi
A20: 212C139-3 | B20: ABSOLUTE PRESS SWITCH | D20: 29 | E20: HYDRAUL | F20: 132 | G20: 3769.61 | I20: =HYPERLINK("\\avrasya\THY_BSK_TEKNIK\MD_TEKNIK_ANLASMALAR_VE_ODEMELER\Teknik Envanter Takip Şefliği\IPC\A310\" &D20&"\"& A20 & ".png", "Resim için basınız") -> Resim için basınız
A21: 9000003-3 | B21: ACCELEROMETER | D21: 27 | E21: ATE | F21: 92 | G21: 81870.61 | I21: =HYPERLINK("\\avrasya\THY_BSK_TEKNIK\MD_TEKNIK_ANLASMALAR_VE_ODEMELER\Teknik Envanter Takip Şefliği\IPC\A310\" &D21&"\"& A21 & ".png", "Resim için basınız") -> Resim için basınız
A22: 30730 | B22: ACCUMULATOR ASSY | D22: 29 | E22: HYDRAUL | F22: 143 | G22: 31304.18 | I22: =HYPERLINK("\\avrasya\THY_BSK_TEKNIK\MD_TEKNIK_ANLASMALAR_VE_ODEMELER\Teknik Envanter Takip Şefliği\IPC\A310\" &D22&"\"& A22 & ".png", "Resim için basınız") -> Resim için basınız
A23: RD-FA3951-01 | B23: ACTIVE USB HUB | D23: 23 | E23: IFE | F23: 562 | G23: 70033.79 | I23: =HYPERLINK("\\avrasya\THY_BSK_TEKNIK\MD_TEKNIK_ANLASMALAR_VE_ODEMELER\Teknik Envanter Takip Şefliği\IPC\A310\" &D23&"\"& A23 & ".png", "Resim için basınız") -> Resim için basınız
A24: LPB1030 | B24: ACTUATOR | D24: 25 | E24: ELECTMEC | F24: 499 | G24: 544563.53 | I24: =HYPERLINK("\\avrasya\THY_BSK_TEKNIK\MD_TEKNIK_ANLASMALAR_VE_ODEMELER\Teknik Envanter Takip Şefliği\IPC\A310\" &D24&"\"& A24 & ".png", "Resim için basınız") -> Resim için basınız
A25: AD8650503 | B25: ACTUATOR | D25: 25 | E25: ELECTMEC | F25: 73 | G25: 96214.98 | I25: =HYPERLINK("\\avrasya\THY_BSK_TEKNIK\MD_TEKNIK_ANLASMALAR_VE_ODEMELER\Teknik Envanter Takip Şefliği\IPC\A310\" &D25&"\"& A25 & ".png", "Resim için basınız") -> Resim için basınız
A26: 904800-01 | B26: ACTUATOR | D26: 52 | E26: ELECTMEC | F26: 387 | G26: 123899.77 | I26: =HYPERLINK("\\avrasya\THY_BSK_TEKNIK\MD_TEKNIK_ANLASMALAR_VE_ODEMELER\Teknik Envanter Takip Şefliği\IPC\A310\" &D26&"\"& A26 & ".png", "Resim için basınız") -> Resim için basınız
A27: RPB1030 | B27: ACTUATOR | D27: 25 | E27: SEAT | F27: 89 | G27: 32838.27 | I27: =HYPERLINK("\\avrasya\THY_BSK_TEKNIK\MD_TEKNIK_ANLASMALAR_VE_ODEMELER\Teknik Envanter Takip Şefliği\IPC\A310\" &D27&"\"& A27 & ".png", "Resim için basınız") -> Resim için basınız
A28: MA30A1001 | B28: ACTUATOR | D28: 28 | E28: ELECTMEC | F28: 555 | G28: 154544.89 | I28: =HYPERLINK("\\avrasya\THY_BSK_TEKNIK\MD_TEKNIK_ANLASMALAR_VE_ODEMELER\Teknik Envanter Takip Şefliği\IPC\A310\" &D28&"\"& A28 & ".png", "Resim için basınız") -> Resim için basınız
A29: MA30A1017 | B29: ACTUATOR | D29: 28 | E29: ELECTMEC | F29: 408 | G29: 154544.89 | I29: =HYPERLINK("\\avrasya\THY_BSK_TEKNIK\MD_TEKNIK_ANLASMALAR_VE_ODEMELER\Teknik Envanter Takip Şefliği\IPC\A310\" &D29&"\"& A29 & ".png", "Resim için basınız") -> Resim için basınız
A30: MA20A2027 | B30: ACTUATOR | D30: 28 | E30: ELECTMEC | F30: 10 | G30: 49740.75 | I30: =HYPERLINK("\\avrasya\THY_BSK_TEKNIK\MD_TEKNIK_ANLASMALAR_VE_ODEMELER\Teknik Envanter Takip Şefliği\IPC\A310\" &D30&"\"& A30 & ".png", "Resim için basınız") -> Resim için basınız
A31: 2A258-0487 | B31: ACTUATOR | D31: 25 | E31: ELECTMEC | F31: 50 | G31: 96298.38 | I31: =HYPERLINK("\\avrasya\THY_BSK_TEKNIK\MD_TEKNIK_ANLASMALAR_VE_ODEMELER\Teknik Envanter Takip Şefliği\IPC\A310\" &D31&"\"& A31 & ".png", "Resim için basınız") -> Resim için basınız
... A2934: 2253M40G06 | B2934: INNER LINER COMBUSTOR | D2934: 72 | E2934: ENGINE | F2934: 1 | G2934: 0 | I2934: =HYPERLINK("\\avrasya\THY_BSK_TEKNIK\MD_TEKNIK_ANLASMALAR_VE_ODEMELER\Teknik Envanter Takip Şefliği\IPC\A310\" &D2934&"\"& A2934 & ".png", "Resim için basınız") -> Resim için basınız

Sheet A319
A1: PID_PN | B1: PN DESC | C1: ilgili | D1: Chapter | E1: Sub Category | F1: QTY | G1: Fa Amount | H1: Fonksiyonu | I1: Görsel | J1: Resim Notu
A2: 3840160-8 | B2: 1.STG.TURBINE ROTOR ASSY. | C2: TAHA | D2: 49 | E2: WHEEL | F2: 6 | G2: 143000 | H2: Yanma odasından çıkan sıcak ve yüksek basınçlı (Bleed Air) gazı enerjiye çevirerek kompresörün ve motor aksesuarlarının dönmesini sağlar | I2: =HYPERLINK("\\avrasya\THY_BSK_TEKNIK\MD_TEKNIK_ANLASMALAR_VE_ODEMELER\Teknik Envanter Takip Şefliği\IPC\A319\" &D2&"\"& A2 & ".png", "Resim için basınız") -> Resim için basınız | J2: Resim girildi
A3: 3840310-3 | B3: 1.STG.TURBINE ROTOR ASSY. | C3: TAHA | D3: 49 | E3: WHEEL | F3: 31 | G3: 1885048.1 | H3: Yanma odasından çıkan sıcak ve yüksek basınçlı (Bleed Air) gazı enerjiye çevirerek kompresörün ve motor aksesuarlarının dönmesini sağlar | I3: =HYPERLINK("\\avrasya\THY_BSK_TEKNIK\MD_TEKNIK_ANLASMALAR_VE_ODEMELER\Teknik Envanter Takip Şefliği\IPC\A319\" &D3&"\"& A3 & ".png", "Resim için basınız") -> Resim için basınız | J3: Resim girildi
A4: 3840310-4 | B4: 1.STG.TURBINE ROTOR ASSY. | C4: TAHA | D4: 49 | E4: WHEEL | F4: 242 | G4: 1913751.7 | H4: Yanma odasından çıkan sıcak ve yüksek basınçlı (Bleed Air) gazı enerjiye çevirerek kompresörün ve motor aksesuarlarının dönmesini sağlar | I4: =HYPERLINK("\\avrasya\THY_BSK_TEKNIK\MD_TEKNIK_ANLASMALAR_VE_ODEMELER\Teknik Envanter Takip Şefliği\IPC\A319\" &D4&"\"& A4 & ".png", "Resim için basınız") -> Resim için basınız | J4: Resim girildi
A5: D23627000 | B5: 1M UPPER ELEC.HARNESS | D5: 32 | E5: INSTRMNT | F5: 82 | G5: 18208.8 | I5: =HYPERLINK("\\avrasya\THY_BSK_TEKNIK\MD_TEKNIK_ANLASMALAR_VE_ODEMELER\Teknik Envanter Takip Şefliği\IPC\A319\" &D5&"\"& A5 & ".png", "Resim için basınız") -> Resim için basınız
A6: D23627000-1 | B6: 1M UPPER ELEC.HARNESS | D6: 32 | E6: INSTRMNT | F6: 8 | G6: 463103.89 | I6: =HYPERLINK("\\avrasya\THY_BSK_TEKNIK\MD_TEKNIK_ANLASMALAR_VE_ODEMELER\Teknik Envanter Takip Şefliği\IPC\A319\" &D6&"\"& A6 & ".png", "Resim için basınız") -> Resim için basınız
A7: 4520563 | B7: 1ST STG TURBINE DISK ASSEMBLY | D7: 49 | E7: FUEL | F7: 7 | G7: 3416407.5 | I7: =HYPERLINK("\\avrasya\THY_BSK_TEKNIK\MD_TEKNIK_ANLASMALAR_VE_ODEMELER\Teknik Envanter Takip Şefliği\IPC\A319\" &D7&"\"& A7 & ".png", "Resim için basınız") -> Resim için basınız
A8: 4505475 | B8: 1ST STG TURBINE WHEEL ASY | D8: 49 | E8: FUEL | F8: 36 | G8: 3129113.3 | I8: =HYPERLINK("\\avrasya\THY_BSK_TEKNIK\MD_TEKNIK_ANLASMALAR_VE_ODEMELER\Teknik Envanter Takip Şefliği\IPC\A319\" &D8&"\"& A8 & ".png", "Resim için basınız") -> Resim için basınız
A9: 2A9002 | B9: 2.STG HPT BLADE | D9: 72 | E9: ENGINE | F9: 471 | G9: 17899.87 | I9: =HYPERLINK("\\avrasya\THY_BSK_TEKNIK\MD_TEKNIK_ANLASMALAR_VE_ODEMELER\Teknik Envanter Takip Şefliği\IPC\A319\" &D9&"\"& A9 & ".png", "Resim için basınız") -> Resim için basınız
A10: 3840165-4 | B10: 2.STG. TURBINE ROTOR ASSY | D10: 49 | E10: WHEEL | F10: 95 | G10: 1177872.9 | I10: =HYPERLINK("\\avrasya\THY_BSK_TEKNIK\MD_TEKNIK_ANLASMALAR_VE_ODEMELER\Teknik Envanter Takip Şefliği\IPC\A319\" &D10&"\"& A10 & ".png", "Resim için basınız") -> Resim için basınız
A11: 3840165-9 | B11: 2.STG. TURBINE WHEEL | D11: 49 | E11: WHEEL | F11: 188 | G11: 1208340.3 | I11: =HYPERLINK("\\avrasya\THY_BSK_TEKNIK\MD_TEKNIK_ANLASMALAR_VE_ODEMELER\Teknik Envanter Takip Şefliği\IPC\A319\" &D11&"\"& A11 & ".png", "Resim için basınız") -> Resim için basınız
A12: D23628000-1 | B12: 2M UPPER ELEC.HARNESS | D12: 32 | E12: INSTRMNT | F12: 73 | G12: 15393.69 | I12: =HYPERLINK("\\avrasya\THY_BSK_TEKNIK\MD_TEKNIK_ANLASMALAR_VE_ODEMELER\Teknik Envanter Takip Şefliği\IPC\A319\" &D12&"\"& A12 & ".png", "Resim için basınız") -> Resim için basınız
A13: D23628000 | B13: 2M UPPER ELEC.HARNESS | D13: 32 | E13: INSTRMNT | F13: 6 | G13: 0 | I13: =HYPERLINK("\\avrasya\THY_BSK_TEKNIK\MD_TEKNIK_ANLASMALAR_VE_ODEMELER\Teknik Envanter Takip Şefliği\IPC\A319\" &D13&"\"& A13 & ".png", "Resim için basınız") -> Resim için basınız
A14: D23628000-2 | B14: 2M UPPER ELEC.HARNESS | D14: 32 | E14: INSTRMNT | F14: 8 | G14: 542362.78 | I14: =HYPERLINK("\\avrasya\THY_BSK_TEKNIK\MD_TEKNIK_ANLASMALAR_VE_ODEMELER\Teknik Envanter Takip Şefliği\IPC\A319\" &D14&"\"& A14 & ".png", "Resim için basınız") -> Resim için basınız
A15: 4505477B | B15: 2ND STG TURBINE WHEEL | D15: 49 | E15: FUEL | F15: 71 | G15: 2587126 | I15: =HYPERLINK("\\avrasya\THY_BSK_TEKNIK\MD_TEKNIK_ANLASMALAR_VE_ODEMELER\Teknik Envanter Takip Şefliği\IPC\A319\" &D15&"\"& A15 & ".png", "Resim için basınız") -> Resim için basınız
A16: 4505477 | B16: 2ND STG TURBINE WHEEL | D16: 49 | E16: FUEL | F16: 3 | G16: 2810163.6 | I16: =HYPERLINK("\\avrasya\THY_BSK_TEKNIK\MD_TEKNIK_ANLASMALAR_VE_ODEMELER\Teknik Envanter Takip Şefliği\IPC\A319\" &D16&"\"& A16 & ".png", "Resim için basınız") -> Resim için basınız
... A45: 5913667-3 | B45: AC GENERATOR | D45: 24 | E45: MECHANIC | F45: 2 | G45: 80270.36 | I45: =HYPERLINK("\\avrasya\THY_BSK_TEKNIK\MD_TEKNIK_ANLASMALAR_VE_ODEMELER\Teknik Envanter Takip Şefliği\IPC\A319\" &D45&"\"& A45 & ".png", "Resim için basınız") -> Resim için basınız
A46: 10826B01E02 | B46: AC POWER DISTRIBUTION UNIT (PDU) | D46: 24 | E46: #N/A | F46: 1 | G46: 89776.05 | I46: =HYPERLINK("\\avrasya\THY_BSK_TEKNIK\MD_TEKNIK_ANLASMALAR_VE_ODEMELER\Teknik Envanter Takip Şefliği\IPC\A319\" &D46&"\"& A46 & ".png", "Resim için basınız") -> Resim için basınız
A47: 5860017-139 | B47: ACC ACTUATOR | D47: 75 | E47: MECHANIC | F47: 9 | G47: 75923.7 | I47: =HYPERLINK("\\avrasya\THY_BSK_TEKNIK\MD_TEKNIK_ANLASMALAR_VE_ODEMELER\Teknik Envanter Takip Şefliği\IPC\A319\" &D47&"\"& A47 & ".png", "Resim için basınız") -> Resim için basınız
A48: 5860017-144 | B48: ACC ACTUATOR | D48: 75 | E48: MECHANIC | F48: 217 | G48: 59572.3 | I48: =HYPERLINK("\\avrasya\THY_BSK_TEKNIK\MD_TEKNIK_ANLASMALAR_VE_ODEMELER\Teknik Envanter Takip Şefliği\IPC\A319\" &D48&"\"& A48 & ".png", "Resim için basınız") -> Resim için basınız
A49: 5860016-139 | B49: ACC VALVE | D49: 75 | E49: MECHANIC | F49: 224 | G49: 827900 | I49: =HYPERLINK("\\avrasya\THY_BSK_TEKNIK\MD_TEKNIK_ANLASMALAR_VE_ODEMELER\Teknik Envanter Takip Şefliği\IPC\A319\" &D49&"\"& A49 & ".png", "Resim için basınız") -> Resim için basınız
A50: J172ABM01 | B50: ACCELEROMETER UNIT | D50: 27 | E50: INSTRMNT | F50: 888 | G50: 223548.8 | I50: =HYPERLINK("\\avrasya\THY_BSK_TEKNIK\MD_TEKNIK_ANLASMALAR_VE_ODEMELER\Teknik Envanter Takip Şefliği\IPC\A319\" &D50&"\"& A50 & ".png", "Resim için basınız") -> Resim için basınız
A51: J172ABM | B51: ACCELEROMETER UNIT | D51: 27 | E51: INSTRMNT | F51: 39 | G51: 83711.36 | I51: =HYPERLINK("\\avrasya\THY_BSK_TEKNIK\MD_TEKNIK_ANLASMALAR_VE_ODEMELER\Teknik Envanter Takip Şefliği\IPC\A319\" &D51&"\"& A51 & ".png", "Resim için basınız") -> Resim için basınız
A52: D5248570001000 | B52: ACCESS DOOR RH | D52: 52 | E52: INSTRMNT | F52: 26 | G52: 1722.95 | I52: =HYPERLINK("\\avrasya\THY_BSK_TEKNIK\MD_TEKNIK_ANLASMALAR_VE_ODEMELER\Teknik Envanter Takip Şefliği\IPC\A319\" &D52&"\"& A52 & ".png", "Resim için basınız") -> Resim için basınız
A53: D2827105300600 | B53: ACT 3 | D53: 28 | E53: INSTRMNT | F53: 1 | G53: 0 | I53: =HYPERLINK("\\avrasya\THY_BSK_TEKNIK\MD_TEKNIK_ANLASMALAR_VE_ODEMELER\Teknik Envanter Takip Şefliği\IPC\A319\" &D53&"\"& A53 & ".png", "Resim için basınız") -> Resim için basınız
A54: D2827105500600 | B54: ACT 5 | D54: 28 | E54: INSTRMNT | F54: 1 | G54: 0 | I54: =HYPERLINK("\\avrasya\THY_BSK_TEKNIK\MD_TEKNIK_ANLASMALAR_VE_ODEMELER\Teknik Envanter Takip Şefliği\IPC\A319\" &D54&"\"& A54 & ".png", "Resim için basınız") -> Resim için basınız
A55: D2827105600600 | B55: ACT 6 | D55: 28 | E55: INSTRMNT | F55: 1 | G55: 0 | I55: =HYPERLINK("\\avrasya\THY_BSK_TEKNIK\MD_TEKNIK_ANLASMALAR_VE_ODEMELER\Teknik Envanter Takip Şefliği\IPC\A319\" &D55&"\"& A55 & ".png", "Resim için basınız") -> Resim için basınız
A56: 738275-3-5 | B56: ACT.FUEL MANAGE. QTY.COMP | D56: 28 | E56: SANITARY | F56: 3 | G56: 39601.04 | I56: =HYPERLINK("\\avrasya\THY_BSK_TEKNIK\MD_TEKNIK_ANLASMALAR_VE_ODEMELER\Teknik Envanter Takip Şefliği\IPC\A319\" &D56&"\"& A56 & ".png", "Resim için basınız") -> Resim için basınız
A57: D3221408000000 | B57: ACTUATING CYL.PIN ASSY | D57: 32 | E57: INSTRMNT | F57: 179 | G57: 33921.27 | I57: =HYPERLINK("\\avrasya\THY_BSK_TEKNIK\MD_TEKNIK_ANLASMALAR_VE_ODEMELER\Teknik Envanter Takip Şefliği\IPC\A319\" &D57&"\"& A57 & ".png", "Resim için basınız") -> Resim için basınız
A58: D3221407920000 | B58: ACTUATING CYLINDER SLEEVE | D58: 32 | E58: INSTRMNT | F58: 179 | G58: 29207.43 | I58: =HYPERLINK("\\avrasya\THY_BSK_TEKNIK\MD_TEKNIK_ANLASMALAR_VE_ODEMELER\Teknik Envanter Takip Şefliği\IPC\A319\" &D58&"\"& A58 & ".png", "Resim için basınız") -> Resim için basınız
... A69: A06L00 | B69: ACTUATOR ELECTRIC | D69: 29 | E69: GALLEY | F69: 62 | G69: 7537.61 | I69: =HYPERLINK("\\avrasya\THY_BSK_TEKNIK\MD_TEKNIK_ANLASMALAR_VE_ODEMELER\Teknik Envanter Takip Şefliği\IPC\A319\" &D69&"\"& A69 & ".png", "Resim için basınız") -> Resim için basınız
A70: 41-2-1100-02 | B70: ACTUATOR EMERGENCY RAM | D70: 21 | E70: FUEL | F70: 203 | G70: 17687.02 | I70: =HYPERLINK("\\avrasya\THY_BSK_TEKNIK\MD_TEKNIK_ANLASMALAR_VE_ODEMELER\Teknik Envanter Takip Şefliği\IPC\A320\" &D70&"\"& A70 & ".png", "Resim için basınız") -> Resim için basınız
A71: 321-409-900-0 | B71: ACTUATOR JUNCTION BOX | D71: 78 | E71: WHEEL | F71: 2 | G71: 39386.55 | I71: =HYPERLINK("\\avrasya\THY_BSK_TEKNIK\MD_TEKNIK_ANLASMALAR_VE_ODEMELER\Teknik Envanter Takip Şefliği\IPC\A320\" &D71&"\"& A71 & ".png", "Resim için basınız") -> Resim için basınız
A72: 4136290006 | B72: ACTUATOR_LABINAL | D72: 25 | E72: FUEL | F72: 505 | G72: 300126.96 | I72: =HYPERLINK("\\avrasya\THY_BSK_TEKNIK\MD_TEKNIK_ANLASMALAR_VE_ODEMELER\Teknik Envanter Takip Şefliği\IPC\A320\" &D72&"\"& A72 & ".png", "Resim için basınız") -> Resim için basınız
A73: 4136290007 | B73: ACTUATOR_LABINAL | D73: 25 | E73: FUEL | F73: 4 | G73: 35645.16 | I73: =HYPERLINK("\\avrasya\THY_BSK_TEKNIK\MD_TEKNIK_ANLASMALAR_VE_ODEMELER\Teknik Envanter Takip Şefliği\IPC\A320\" &D73&"\"& A73 & ".png", "Resim için basınız") -> Resim için basınız
A74: 321-400-705-0 | B74: ACTUATOR-DOOR OPENING | D74: 78 | E74: WHEEL | F74: 5 | G74: 432432.9 | I74: =HYPERLINK("\\avrasya\THY_BSK_TEKNIK\MD_TEKNIK_ANLASMALAR_VE_ODEMELER\Teknik Envanter Takip Şefliği\IPC\A320\" &D74&"\"& A74 & ".png", "Resim için basınız") -> Resim için basınız
A75: 321-400-707-0 | B75: ACTUATOR-DOOR OPENING | D75: 78 | E75: WHEEL | F75: 4 | G75: 538782.94 | I75: =HYPERLINK("\\avrasya\THY_BSK_TEKNIK\MD_TEKNIK_ANLASMALAR_VE_ODEMELER\Teknik Envanter Takip Şefliği\IPC\A320\" &D75&"\"& A75 & ".png", "Resim için basınız") -> Resim için basınız
A76: S4-3300520-01 | B76: ACTUATOR-HYDRAULIC | D76: 52 | E76: INSTRMNT | F76: 16 | G76: 5095.35 | I76: =HYPERLINK("\\avrasya\THY_BSK_TEKNIK\MD_TEKNIK_ANLASMALAR_VE_ODEMELER\Teknik Envanter Takip Şefliği\IPC\A320\" &D76&"\"& A76 & ".png", "Resim için basınız") -> Resim için basınız
A77: E20000 | B77: ACTUATOR-HYDRAULIC | D77: 52 | E77: INSTRMNT | F77: 806 | G77: 99641 | I77: =HYPERLINK("\\avrasya\THY_BSK_TEKNIK\MD_TEKNIK_ANLASMALAR_VE_ODEMELER\Teknik Envanter Takip Şefliği\IPC\A320\" &D77&"\"& A77 & ".png", "Resim için basınız") -> Resim için basınız
A78: S4-3300520 | B78: ACTUATOR-HYDRAULIC | D78: 52 | E78: INSTRMNT | F78: 4 | G78: 59727.68 | I78: =HYPERLINK("\\avrasya\THY_BSK_TEKNIK\MD_TEKNIK_ANLASMALAR_VE_ODEMELER\Teknik Envanter Takip Şefliği\IPC\A320\" &D78&"\"& A78 & ".png", "Resim için basınız") -> Resim için basınız
...

Sheet A320
A1: PID_PN | B1: PN DESC | C1: ilgili | D1: Chapter | E1: Sub Category | F1: QTY | G1: FA Amount | H1: Fonksiyonu | I1: Görsel | J1: Resim notu
A2: 3840160-8 | B2: 1.STG.TURBINE ROTOR ASSY. | D2: 49 | E2: APU | F2: 6 | G2: 143000 | I2: =HYPERLINK("\\avrasya\THY_BSK_TEKNIK\MD_TEKNIK_ANLASMALAR_VE_ODEMELER\Teknik Envanter Takip Şefliği\IPC\A320\" &D2&"\"& A2 & ".png", "Resim için basınız") -> Resim için basınız
A3: 3840310-3 | B3: 1.STG.TURBINE ROTOR ASSY. | D3: 49 | E3: APU | F3: 31 | G3: 1885048.1 | I3: =HYPERLINK("\\avrasya\THY_BSK_TEKNIK\MD_TEKNIK_ANLASMALAR_VE_ODEMELER\Teknik Envanter Takip Şefliği\IPC\A320\" &D3&"\"& A3 & ".png", "Resim için basınız") -> Resim için basınız
A4: 3840310-4 | B4: 1.STG.TURBINE ROTOR ASSY. | D4: 49 | E4: APU | F4: 240 | G4: 1913751.7 | I4: =HYPERLINK("\\avrasya\THY_BSK_TEKNIK\MD_TEKNIK_ANLASMALAR_VE_ODEMELER\Teknik Envanter Takip Şefliği\IPC\A320\" &D4&"\"& A4 & ".png", "Resim için basınız") -> Resim için basınız
A5: 201158007 | B5: 1M ELECT.HARNESS,AXLE-LH | C5: TAHA | D5: 32 | E5: HARNESS | F5: 1 | G5: 0 | H5: İniş Takımı aksı üzerinde elektrik kablolarını taşıyarak sistemin elektriksel bağlantısını sağlar | I5: =HYPERLINK("\\avrasya\THY_BSK_TEKNIK\MD_TEKNIK_ANLASMALAR_VE_ODEMELER\Teknik Envanter Takip Şefliği\IPC\A320\32\"& A5 & ".png", "Resim için basınız") -> Resim için basınız | J5: Resim girildi
A6: 201134016 | B6: 1M ELECT.HARNESS,LEG-R/H | C6: TAHA | D6: 32 | E6: HARNESS | F6: 1 | G6: 0 | H6: İniş takımı bacağı boyunca elektrik sinyallerini sensörlere ve kontrol sistemine ileterek iniş takımı sisteminin çalışmasını sağlar | I6: =HYPERLINK("\\avrasya\THY_BSK_TEKNIK\MD_TEKNIK_ANLASMALAR_VE_ODEMELER\Teknik Envanter Takip Şefliği\IPC\A320\" &D6&"\"& A6 & ".png", "Resim için basınız") -> Resim için basınız | J6: Resim girildi
A7: D23627000 | B7: 1M UPPER ELEC.HARNESS | C7: TAHA | D7: 32 | E7: HARNESS | F7: 82 | G7: 18208.8 | H7: İniş takımı üst kısımdaki sensör, gösterge ve kontrol bileşenlerine elektrik bağlantısı sağlayarak sistemin veri ve güç akışını gerçekleştirir. | I7: =HYPERLINK("\\avrasya\THY_BSK_TEKNIK\MD_TEKNIK_ANLASMALAR_VE_ODEMELER\Teknik Envanter Takip Şefliği\IPC\A320\" &D7&"\"& A7 & ".png", "Resim için basınız") -> Resim için basınız | J7: Resim girildi
A8: D23627000-1 | B8: 1M UPPER ELEC.HARNESS | C8: TAHA | D8: 32 | E8: HARNESS | F8: 8 | G8: 463103.89 | H8: İniş takımı üst kısımdaki sensör, gösterge ve kontrol bileşenlerine elektrik bağlantısı sağlayarak sistemin veri ve güç akışını gerçekleştirir. | I8: =HYPERLINK("\\avrasya\THY_BSK_TEKNIK\MD_TEKNIK_ANLASMALAR_VE_ODEMELER\Teknik Envanter Takip Şefliği\IPC\A320\" &D8&"\"& A8 & ".png", "Resim için basınız") -> Resim için basınız | J8: Resim girildi
A9: 4520563 | B9: 1ST STG TURBINE DISK ASSEMBLY | C9: TAHA | D9: 49 | E9: APU | F9: 7 | G9: 3416407.5 | H9: Yanma odasından gelen sıcak gazı mekanik enerjiye çevirerek APU kompresörünün ve jeneratörünün dönmesini sağlar | I9: =HYPERLINK("\\avrasya\THY_BSK_TEKNIK\MD_TEKNIK_ANLASMALAR_VE_ODEMELER\Teknik Envanter Takip Şefliği\IPC\A320\" &D9&"\"& A9 & ".png", "Resim için basınız") -> Resim için basınız | J9: Resim girildi
A10: 4505475 | B10: 1ST STG TURBINE WHEEL ASY | D10: 49 | E10: APU | F10: 36 | G10: 3129113.3 | I10: =HYPERLINK("\\avrasya\THY_BSK_TEKNIK\MD_TEKNIK_ANLASMALAR_VE_ODEMELER\Teknik Envanter Takip Şefliği\IPC\A320\" &D10&"\"& A10 & ".png", "Resim için basınız") -> Resim için basınız
A11: 2A9002 | B11: 2.STG HPT BLADE | D11: 72 | E11: ENGINE | F11: 471 | G11: 17899.87 | I11: =HYPERLINK("\\avrasya\THY_BSK_TEKNIK\MD_TEKNIK_ANLASMALAR_VE_ODEMELER\Teknik Envanter Takip Şefliği\IPC\A320\" &D11&"\"& A11 & ".png", "Resim için basınız") -> Resim için basınız
A12: 3840165-4 | B12: 2.STG. TURBINE ROTOR ASSY | D12: 49 | E12: APU | F12: 95 | G12: 1177872.9 | I12: =HYPERLINK("\\avrasya\THY_BSK_TEKNIK\MD_TEKNIK_ANLASMALAR_VE_ODEMELER\Teknik Envanter Takip Şefliği\IPC\A320\" &D12&"\"& A12 & ".png", "Resim için basınız") -> Resim için basınız
A13: 3840165-9 | B13: 2.STG. TURBINE WHEEL | D13: 49 | E13: APU | F13: 186 | G13: 1208340.3 | I13: =HYPERLINK("\\avrasya\THY_BSK_TEKNIK\MD_TEKNIK_ANLASMALAR_VE_ODEMELER\Teknik Envanter Takip Şefliği\IPC\A320\" &D13&"\"& A13 & ".png", "Resim için basınız") -> Resim için basınız
A14: 201168021 | B14: 2M ELECT,HARNESS,LEG-L/H | D14: 32 | E14: HARNESS | F14: 1 | G14: 0 | I14: =HYPERLINK("\\avrasya\THY_BSK_TEKNIK\MD_TEKNIK_ANLASMALAR_VE_ODEMELER\Teknik Envanter Takip Şefliği\IPC\A320\" &D14&"\"& A14 & ".png", "Resim için basınız") -> Resim için basınız
A15: D23628000-1 | B15: 2M UPPER ELEC.HARNESS | D15: 32 | E15: HARNESS | F15: 73 | G15: 15393.69 | I15: =HYPERLINK("\\avrasya\THY_BSK_TEKNIK\MD_TEKNIK_ANLASMALAR_VE_ODEMELER\Teknik Envanter Takip Şefliği\IPC\A320\" &D15&"\"& A15 & ".png", "Resim için basınız") -> Resim için basınız
A16: D23628000 | B16: 2M UPPER ELEC.HARNESS | D16: 32 | E16: HARNESS | F16: 6 | G16: 0 | I16: =HYPERLINK("\\avrasya\THY_BSK_TEKNIK\MD_TEKNIK_ANLASMALAR_VE_ODEMELER\Teknik Envanter Takip Şefliği\IPC\A320\" &D16&"\"& A16 & ".png", "Resim için basınız") -> Resim için basınız
A17: 10-375401-001 | B17: 2M UPPER ELEC.HARNESS | D17: 32 | E17: HARNESS | F17: 5 | G17: 294948.58 | I17: =HYPERLINK("\\avrasya\THY_BSK_TEKNIK\MD_TEKNIK_ANLASMALAR_VE_ODEMELER\Teknik Envanter Takip Şefliği\IPC\A320\" &D17&"\"& A17 & ".png", "Resim için basınız") -> Resim için basınız
A18: D23628000-2 | B18: 2M UPPER ELEC.HARNESS | D18: 32 | E18: HARNESS | F18: 8 | G18: 542362.78 | I18: =HYPERLINK("\\avrasya\THY_BSK_TEKNIK\MD_TEKNIK_ANLASMALAR_VE_ODEMELER\Teknik Envanter Takip Şefliği\IPC\A320\" &D18&"\"& A18 & ".png", "Resim için basınız") -> Resim için basınız
A19: 4505477B | B19: 2ND STG TURBINE WHEEL | D19: 49 | E19: APU | F19: 71 | G19: 2587126 | I19: =HYPERLINK("\\avrasya\THY_BSK_TEKNIK\MD_TEKNIK_ANLASMALAR_VE_ODEMELER\Teknik Envanter Takip Şefliği\IPC\A320\" &D19&"\"& A19 & ".png", "Resim için basınız") -> Resim için basınız
A20: 4505477 | B20: 2ND STG TURBINE WHEEL | D20: 49 | E20: APU | F20: 3 | G20: 2810163.6 | I20: =HYPERLINK("\\avrasya\THY_BSK_TEKNIK\MD_TEKNIK_ANLASMALAR_VE_ODEMELER\Teknik Envanter Takip Şefliği\IPC\A320\" &D20&"\"& A20 & ".png", "Resim için basınız") -> Resim için basınız
A21: 4520482 | B21: 2ND STG TURBINE WHEEL | D21: 49 | E21: APU | F21: 32 | G21: 2810163.6 | I21: =HYPERLINK("\\avrasya\THY_BSK_TEKNIK\MD_TEKNIK_ANLASMALAR_VE_ODEMELER\Teknik Envanter Takip Şefliği\IPC\A320\" &D21&"\"& A21 & ".png", "Resim için basınız") -> Resim için basınız
A22: S4-3400950-06 | B22: 3-2 WAY VALVE | D22: 29 | E22: HYDRAUL | F22: 1 | G22: 6324.23 | I22: =HYPERLINK("\\avrasya\THY_BSK_TEKNIK\MD_TEKNIK_ANLASMALAR_VE_ODEMELER\Teknik Envanter Takip Şefliği\IPC\A320\" &D22&"\"& A22 & ".png", "Resim için basınız") -> Resim için basınız
A23: RD-AA8190-01 | B23: 4G ENHANCED CELL MODEM (4G ECM) | D23: 23 | E23: IFE | F23: 247 | G23: 898253.44 | I23: =HYPERLINK("\\avrasya\THY_BSK_TEKNIK\MD_TEKNIK_ANLASMALAR_VE_ODEMELER\Teknik Envanter Takip Şefliği\IPC\A320\" &D23&"\"& A23 & ".png", "Resim için basınız") -> Resim için basınız
A24: AA1051-00 | B24: 7HP COMP.SOLENOID VALVE | D24: 75 | E24: PNEUMATC | F24: 389 | G24: 111512.19 | I24: =HYPERLINK("\\avrasya\THY_BSK_TEKNIK\MD_TEKNIK_ANLASMALAR_VE_ODEMELER\Teknik Envanter Takip Şefliği\IPC\A320\" &D24&"\"& A24 & ".png", "Resim için basınız") -> Resim için basınız
A25: AA1056-00 | B25: 7HP COMP.SOLENOID VALVE | D25: 75 | E25: PNEUMATC | F25: 377 | G25: 54586.77 | I25: =HYPERLINK("\\avrasya\THY_BSK_TEKNIK\MD_TEKNIK_ANLASMALAR_VE_ODEMELER\Teknik Envanter Takip Şefliği\IPC\A320\" &D25&"\"& A25 & ".png", "Resim için basınız") -> Resim için basınız
A26: AC69572 | B26: 7HP COMP.SOLENOID VALVE | D26: 75 | E26: PNEUMATC | F26: 12 | G26: 49938 | I26: =HYPERLINK("\\avrasya\THY_BSK_TEKNIK\MD_TEKNIK_ANLASMALAR_VE_ODEMELER\Teknik Envanter Takip Şefliği\IPC\A320\" &D26&"\"& A26 & ".png", "Resim için basınız") -> Resim için basınız
A27: 617-6231-001 | B27: 8.6? LH LCD RETRACT MON | D27: 23 | E27: IFE | F27: 1 | G27: 4964.7 | I27: =HYPERLINK("\\avrasya\THY_BSK_TEKNIK\MD_TEKNIK_ANLASMALAR_VE_ODEMELER\Teknik Envanter Takip Şefliği\IPC\A320\" &D27&"\"& A27 & ".png", "Resim için basınız") -> Resim için basınız
A28: 617-6231-002 | B28: 8.6? RH LCD RETRACT MON. | D28: 23 | E28: IFE | F28: 1 | G28: 0.01 | I28: =HYPERLINK("\\avrasya\THY_BSK_TEKNIK\MD_TEKNIK_ANLASMALAR_VE_ODEMELER\Teknik Envanter Takip Şefliği\IPC\A320\" &D28&"\"& A28 & ".png", "Resim için basınız") -> Resim için basınız
A29: RD-AV9843-01 | B29: 10.4? LCD COLOR MONITOR | D29: 23 | E29: IFE | F29: 60 | G29: 0 | I29: =HYPERLINK("\\avrasya\THY_BSK_TEKNIK\MD_TEKNIK_ANLASMALAR_VE_ODEMELER\Teknik Envanter Takip Şefliği\IPC\A320\" &D29&"\"& A29 & ".png", "Resim için basınız") -> Resim için basınız
A30: RD-AV9844-01 | B30: 10.4? LCD DISPLAY | D30: 23 | E30: IFE | F30: 60 | G30: 0 | I30: =HYPERLINK("\\avrasya\THY_BSK_TEKNIK\MD_TEKNIK_ANLASMALAR_VE_ODEMELER\Teknik Envanter Takip Şefliği\IPC\A320\" &D30&"\"& A30 & ".png", "Resim için basınız") -> Resim için basınız
A31: TP0311-001 | B31: 10" CREW CONTROL PANEL | D31: 44 | E31: IFE | F31: 58 | G31: 95852.8 | I31: =HYPERLINK("\\avrasya\THY_BSK_TEKNIK\MD_TEKNIK_ANLASMALAR_VE_ODEMELER\Teknik Envanter Takip Şefliği\IPC\A320\" &D31&"\"& A31 & ".png", "Resim için basınız") -> Resim için basınız
A32: AA1064-00 | B32: 10HP COMP.SOLENOID VALVE | D32: 75 | E32: PNEUMATC | F32: 134 | G32: 48121.58 | I32: =HYPERLINK("\\avrasya\THY_BSK_TEKNIK\MD_TEKNIK_ANLASMALAR_VE_ODEMELER\Teknik Envanter Takip Şefliği\IPC\A320\" &D32&"\"& A32 & ".png", "Resim için basınız") -> Resim için basınız
A33: AA1060-00 | B33: 10HP COMP.SOLENOID VALVE | D33: 75 | E33: PNEUMATC | F33: 122 | G33: 240191.39 | I33: =HYPERLINK("\\avrasya\THY_BSK_TEKNIK\MD_TEKNIK_ANLASMALAR_VE_ODEMELER\Teknik Envanter Takip Şefliği\IPC\A320\" &D33&"\"& A33 & ".png", "Resim için basınız") -> Resim için basınız
... A53: 6610-20567-01 | B53: ACTUATOR | D53: 36 | E53: ELECTMEC | F53: 69 | G53: 250489.87 | I53: =HYPERLINK("\\avrasya\THY_BSK_TEKNIK\MD_TEKNIK_ANLASMALAR_VE_ODEMELER\Teknik Envanter Takip Şefliği\IPC\A320\" &D53&"\"& A53 & ".png", "Resim için basınız") -> Resim için basınız
A54: 1809A0000-01 | B54: ACTUATOR - INLET | C54: TAHA | D54: 21 | E54: ELECTMEC | F54: 419 | G54: 493027.36 | H54: Motorun ön kısmındaki hava giriş yapısını hareket ettirerek hava akışını ve buzlanma önlemini kontrol eder | I54: =HYPERLINK("\\avrasya\THY_BSK_TEKNIK\MD_TEKNIK_ANLASMALAR_VE_ODEMELER\Teknik Envanter Takip Şefliği\IPC\A320\" &D54&"\"& A54 & ".png", "Resim için basınız") -> Resim için basınız | J54: Resim girildi
A55: AD8552502-1 | B55: ACTUATOR ARTUS | D55: 25 | E55: ELECTMEC | F55: 9 | G55: 117647.88 | I55: =HYPERLINK("\\avrasya\THY_BSK_TEKNIK\MD_TEKNIK_ANLASMALAR_VE_ODEMELER\Teknik Envanter Takip Şefliği\IPC\A320\" &D55&"\"& A55 & ".png", "Resim için basınız") -> Resim için basınız
A56: 4504086 | B56: ACTUATOR ASSY | D56: 49 | E56: FUEL | F56: 32 | G56: 104212.19 | I56: =HYPERLINK("\\avrasya\THY_BSK_TEKNIK\MD_TEKNIK_ANLASMALAR_VE_ODEMELER\Teknik Envanter Takip Şefliği\IPC\A320\" &D56&"\"& A56 & ".png", "Resim için basınız") -> Resim için basınız
A57: 4510835 | B57: ACTUATOR ASSY | D57: 49 | E57: FUEL | F57: 68 | G57: 101313.75 | I57: =HYPERLINK("\\avrasya\THY_BSK_TEKNIK\MD_TEKNIK_ANLASMALAR_VE_ODEMELER\Teknik Envanter Takip Şefliği\IPC\A320\" &D57&"\"& A57 & ".png", "Resim için basınız") -> Resim için basınız
A58: A05000 | B58: ACTUATOR ASSY | D58: 38 | E58: ELECTMEC | F58: 34 | G58: 18952.28 | I58: =HYPERLINK("\\avrasya\THY_BSK_TEKNIK\MD_TEKNIK_ANLASMALAR_VE_ODEMELER\Teknik Envanter Takip Şefliği\IPC\A320\" &D58&"\"& A58 & ".png", "Resim için basınız") -> Resim için basınız
A59: B27000 | B59: ACTUATOR ASSY | D59: 28 | E59: ELECTMEC | F59: 3 | G59: 6794.88 | I59: =HYPERLINK("\\avrasya\THY_BSK_TEKNIK\MD_TEKNIK_ANLASMALAR_VE_ODEMELER\Teknik Envanter Takip Şefliği\IPC\A320\" &D59&"\"& A59 & ".png", "Resim için basınız") -> Resim için basınız
...

Sheet A321
A1: PN | B1: PN DESC | C1: ilgili | D1: Chapter | E1: Sub Category | F1: QTY | G1: FA Amount | H1: Fonksiyonu | I1: Görsel | J1: Resim Notu
A2: PW1133GA-JM | B2: PW1100GA-JM ENGINE | D2: 72 | E2: ENGINE | F2: 226 | G2: 4.168259e+08 | I2: =HYPERLINK("\\avrasya\THY_BSK_TEKNIK\MD_TEKNIK_ANLASMALAR_VE_ODEMELER\Teknik Envanter Takip Şefliği\IPC\A321\" &D2&"\"& A2 & ".png", "Resim için basınız") -> Resim için basınız
A3: 10-454301-002 | B3: LEG ASSY AND DRESSINGS, MLG (LH) | D3: 32 | E3: LDG | F3: 14 | G3: 38114000 | I3: =HYPERLINK("\\avrasya\THY_BSK_TEKNIK\MD_TEKNIK_ANLASMALAR_VE_ODEMELER\Teknik Envanter Takip Şefliği\IPC\A321\" &D3&"\"& A3 & ".png", "Resim için basınız") -> Resim için basınız
A4: V2533-A5 | B4: V2500 ENGINE | D4: 72 | E4: ENGINE | F4: 157 | G4: 32875390 | I4: =HYPERLINK("\\avrasya\THY_BSK_TEKNIK\MD_TEKNIK_ANLASMALAR_VE_ODEMELER\Teknik Envanter Takip Şefliği\IPC\A321\" &D4&"\"& A4 & ".png", "Resim için basınız") -> Resim için basınız
A5: 10-375902-005 | B5: NLG LEG ASSY | D5: 32 | E5: LDG | F5: 19 | G5: 15553175 | I5: =HYPERLINK("\\avrasya\THY_BSK_TEKNIK\MD_TEKNIK_ANLASMALAR_VE_ODEMELER\Teknik Envanter Takip Şefliği\IPC\A321\" &D5&"\"& A5 & ".png", "Resim için basınız") -> Resim için basınız
A6: RD-NB2112-02 | B6: SINGLE PANEL GCS ANTENNA (SPA-02) | D6: 23 | E6: IFE | F6: 133 | G6: 14274280 | I6: =HYPERLINK("\\avrasya\THY_BSK_TEKNIK\MD_TEKNIK_ANLASMALAR_VE_ODEMELER\Teknik Envanter Takip Şefliği\IPC\A321\" &D6&"\"& A6 & ".png", "Resim için basınız") -> Resim için basınız
A7: 1020420-3-121 | B7: CONTROL-ELECTRONIC ENGINE | D7: 73 | E7: ATE | F7: 37 | G7: 13753738 | I7: =HYPERLINK("\\avrasya\THY_BSK_TEKNIK\MD_TEKNIK_ANLASMALAR_VE_ODEMELER\Teknik Envanter Takip Şefliği\IPC\A321\" &D7&"\"& A7 & ".png", "Resim için basınız") -> Resim için basınız
A8: 636-2051-519 | B8: RH FAN COWL, ENG 1 | D8: 71 | E8: COMPOSIT | F8: 66 | G8: 13501348 | I8: =HYPERLINK("\\avrasya\THY_BSK_TEKNIK\MD_TEKNIK_ANLASMALAR_VE_ODEMELER\Teknik Envanter Takip Şefliği\IPC\A321\" &D8&"\"& A8 & ".png", "Resim için basınız") -> Resim için basınız
A9: 4500001C | B9: APS3200 | D9: 49 | E9: APU | F9: 86 | G9: 13169175 | I9: =HYPERLINK("\\avrasya\THY_BSK_TEKNIK\MD_TEKNIK_ANLASMALAR_VE_ODEMELER\Teknik Envanter Takip Şefliği\IPC\A321\" &D9&"\"& A9 & ".png", "Resim için basınız") -> Resim için basınız
A10: 1015200-6 | B10: INTEGRATED FUEL CONTROL&PUMP-MAIN | D10: 73 | E10: FUEL | F10: 141 | G10: 12975067 | I10: =HYPERLINK("\\avrasya\THY_BSK_TEKNIK\MD_TEKNIK_ANLASMALAR_VE_ODEMELER\Teknik Envanter Takip Şefliği\IPC\A321\" &D10&"\"& A10 & ".png", "Resim için basınız") -> Resim için basınız
A11: HG2030BE04 | B11: ADIRU | D11: 34 | E11: ATE | F11: 543 | G11: 11803404 | I11: =HYPERLINK("\\avrasya\THY_BSK_TEKNIK\MD_TEKNIK_ANLASMALAR_VE_ODEMELER\Teknik Envanter Takip Şefliği\IPC\A321\" &D11&"\"& A11 & ".png", "Resim için basınız") -> Resim için basınız
A12: HG2030BE03 | B12: ADIRU | D12: 34 | E12: ATE | F12: 125 | G12: 11561484 | I12: =HYPERLINK("\\avrasya\THY_BSK_TEKNIK\MD_TEKNIK_ANLASMALAR_VE_ODEMELER\Teknik Envanter Takip Şefliği\IPC\A321\" &D12&"\"& A12 & ".png", "Resim için basınız") -> Resim için basınız
A13: 9005000-11203 | B13: T3CAS COMPUTER | D13: 34 | E13: RADIO | F13: 21 | G13: 11447780 | I13: =HYPERLINK("\\avrasya\THY_BSK_TEKNIK\MD_TEKNIK_ANLASMALAR_VE_ODEMELER\Teknik Envanter Takip Şefliği\IPC\A321\" &D13&"\"& A13 & ".png", "Resim için basınız") -> Resim için basınız
... A18: 201522281 | B18: SLIDING TUBE SUBASSY | D18: 32 | E18: LDG | F18: 14 | G18: 8794246 | I18: =HYPERLINK("\\avrasya\THY_BSK_TEKNIK\MD_TEKNIK_ANLASMALAR_VE_ODEMELER\Teknik Envanter Takip Şefliği\IPC\A321\" &D18&"\"& A18 & ".png", "Resim için basınız") -> Resim için basınız
A19: 745-3000-515 | B19: INLET COWL | C19: TAHA | D19: 71 | E19: COMPOSIT | F19: 41 | G19: 8417130 | H19: Motorun ön kısmından gelen havayı düzgün şekilde içeri yönlendirerek motorun verimli çalışmasını sağlar ve Fan bölgesini dış etkilerden korur. | I19: =HYPERLINK("\\avrasya\THY_BSK_TEKNIK\MD_TEKNIK_ANLASMALAR_VE_ODEMELER\Teknik Envanter Takip Şefliği\IPC\A321\" &D19&"\"& A19 & ".png", "Resim için basınız") -> Resim için basınız | J19: Resim girildi
A20: RD-KA1003-05 | B20: FILE SERVER | C20: TAHA | D20: 23 | E20: IFE | F20: 39 | G20: 8160765.9 | H20: Dosyaların güvenli bir ortamda saklanmasını sağlayarak kullanıcıların dosyalara güvenli ve sağlıklı bir şekilde ulaşmalarını sağlar | I20: =HYPERLINK("\\avrasya\THY_BSK_TEKNIK\MD_TEKNIK_ANLASMALAR_VE_ODEMELER\Teknik Envanter Takip Şefliği\IPC\A321\" &D20&"\"& A20 & ".png", "Resim için basınız") -> Resim için basınız | J20: Resim girildi
A21: 745-3400-507 | B21: INLET COWL | D21: 71 | E21: COMPOSIT | F21: 143 | G21: 8073740.4 | I21: =HYPERLINK("\\avrasya\THY_BSK_TEKNIK\MD_TEKNIK_ANLASMALAR_VE_ODEMELER\Teknik Envanter Takip Şefliği\IPC\A321\" &D21&"\"& A21 & ".png", "Resim için basınız") -> Resim için basınız
A22: 636-1101-513 | B22: AIR INTAKE ASSY | D22: 71 | E22: COMPOSIT | F22: 36 | G22: 7536488.2 | I22: =HYPERLINK("\\avrasya\THY_BSK_TEKNIK\MD_TEKNIK_ANLASMALAR_VE_ODEMELER\Teknik Envanter Takip Şefliği\IPC\A321\" &D22&"\"& A22 & ".png", "Resim için basınız") -> Resim için basınız
A23: 5322862 | B23: ANGLE GEARBOX MODULE | D23: 72 | E23: ENGINE | F23: 158 | G23: 7363723.8 | I23: =HYPERLINK("\\avrasya\THY_BSK_TEKNIK\MD_TEKNIK_ANLASMALAR_VE_ODEMELER\Teknik Envanter Takip Şefliği\IPC\A321\" &D23&"\"& A23 & ".png", "Resim için basınız") -> Resim için basınız
A24: 5327092 | B24: STARTER-ENGINE,AIR | D24: 80 | E24: PNEUMATC | F24: 113 | G24: 6390849.1 | I24: =HYPERLINK("\\avrasya\THY_BSK_TEKNIK\MD_TEKNIK_ANLASMALAR_VE_ODEMELER\Teknik Envanter Takip Şefliği\IPC\A321\" &D24&"\"& A24 & ".png", "Resim için basınız") -> Resim için basınız
A25: 745-1101-507 | B25: COMMON NOZZLE ASSY (CNA) | D25: 78 | E25: COMPOSIT | F25: 143 | G25: 5782543.8 | I25: =HYPERLINK("\\avrasya\THY_BSK_TEKNIK\MD_TEKNIK_ANLASMALAR_VE_ODEMELER\Teknik Envanter Takip Şefliği\IPC\A321\" &D25&"\"& A25 & ".png", "Resim için basınız") -> Resim için basınız
A26: C12850BC03 | B26: FLIGHT CONTROL UNIT | D26: 22 | E26: ATE | F26: 10 | G26: 5598603 | I26: =HYPERLINK("\\avrasya\THY_BSK_TEKNIK\MD_TEKNIK_ANLASMALAR_VE_ODEMELER\Teknik Envanter Takip Şefliği\IPC\A321\" &D26&"\"& A26 & ".png", "Resim için basınız") -> Resim için basınız
A27: C19755BA01 | B27: ENHANCED LIQ.CRYS.DISP.UN | D27: 31 | E27: ATE | F27: 1088 | G27: 5483816 | I27: =HYPERLINK("\\avrasya\THY_BSK_TEKNIK\MD_TEKNIK_ANLASMALAR_VE_ODEMELER\Teknik Envanter Takip Şefliği\IPC\A321\" &D27&"\"& A27 & ".png", "Resim için basınız") -> Resim için basınız
A28: 201522267 | B28: SLIDING TUBE SUBASSEMBLY | D28: 32 | E28: LDG | F28: 92 | G28: 5388285.6 | I28: =HYPERLINK("\\avrasya\THY_BSK_TEKNIK\MD_TEKNIK_ANLASMALAR_VE_ODEMELER\Teknik Envanter Takip Şefliği\IPC\A321\" &D28&"\"& A28 & ".png", "Resim için basınız") -> Resim için basınız
A29: D2755605501300 | B29: FLAP TRACK N 4 CARRIAGE RH | D29: 27 | E29: STRCTURE | F29: 58 | G29: 5361060.4 | I29: =HYPERLINK("\\avrasya\THY_BSK_TEKNIK\MD_TEKNIK_ANLASMALAR_VE_ODEMELER\Teknik Envanter Takip Şefliği\IPC\A321\" &D29&"\"& A29 & ".png", "Resim için basınız") -> Resim için basınız
A30: C16291AB | B30: AOA SENSOR | C30: TAHA | D30: 34 | E30: INSTRMNT | F30: 738 | G30: 5359342.4 | H30: Angle Of Attack Sensor kanadın hava akışına göre açısını ölçerek stall riskini önlemek için uçuş kontrol sistemine veri sağlar | I30: =HYPERLINK("\\avrasya\THY_BSK_TEKNIK\MD_TEKNIK_ANLASMALAR_VE_ODEMELER\Teknik Envanter Takip Şefliği\IPC\A321\" &D30&"\"& A30 & ".png", "Resim için basınız") -> Resim için basınız | J30: Resim girildi
A31: 47145-247 | B31: THS ACTUATOR | D31: 27 | E31: MECHANIC | F31: 27 | G31: 5354604.3 | I31: =HYPERLINK("\\avrasya\THY_BSK_TEKNIK\MD_TEKNIK_ANLASMALAR_VE_ODEMELER\Teknik Envanter Takip Şefliği\IPC\A321\" &D31&"\"& A31 & ".png", "Resim için basınız") -> Resim için basınız
A32: 5323305 | B32: COOLER-AIR, #4 BEARING | D32: 75 | E32: MECHANIC | F32: 119 | G32: 5104343.2 | I32: =HYPERLINK("\\avrasya\THY_BSK_TEKNIK\MD_TEKNIK_ANLASMALAR_VE_ODEMELER\Teknik Envanter Takip Şefliği\IPC\A321\" &D32&"\"& A32 & ".png", "Resim için basınız") -> Resim için basınız
A33: BA03604 | B33: AC GENERATOR | D33: 24 | E33: IDG/GEN | F33: 46 | G33: 4965131.4 | I33: =HYPERLINK("\\avrasya\THY_BSK_TEKNIK\MD_TEKNIK_ANLASMALAR_VE_ODEMELER\Teknik Envanter Takip Şefliği\IPC\A321\" &D33&"\"& A33 & ".png", "Resim için basınız") -> Resim için basınız
A34: D5757390001051 | B34: LH INBOARD FLAP | D34: 27 | E34: COMPOSIT | F34: 1 | G34: 4937434.9 | I34: =HYPERLINK("\\avrasya\THY_BSK_TEKNIK\MD_TEKNIK_ANLASMALAR_VE_ODEMELER\Teknik Envanter Takip Şefliği\IPC\A321\" &D34&"\"& A34 & ".png", "Resim için basınız") -> Resim için basınız
A35: D5757390001151 | B35: RH INBOARD FLAP | D35: 27 | E35: COMPOSIT | F35: 1 | G35: 4937434.9 | I35: =HYPERLINK("\\avrasya\THY_BSK_TEKNIK\MD_TEKNIK_ANLASMALAR_VE_ODEMELER\Teknik Envanter Takip Şefliği\IPC\A321\" &D35&"\"& A35 & ".png", "Resim için basınız") -> Resim için basınız
A36: B372BAM0515 | B36: SPOILER ELEVATOR COMPUTER | D36: 27 | E36: ATE | F36: 127 | G36: 4874212 | I36: =HYPERLINK("\\avrasya\THY_BSK_TEKNIK\MD_TEKNIK_ANLASMALAR_VE_ODEMELER\Teknik Envanter Takip Şefliği\IPC\A321\" &D36&"\"& A36 & ".png", "Resim için basınız") -> Resim için basınız
A37: B372BBM0104 | B37: SPOILER ELEVATOR COMPUTER | D37: 27 | E37: ATE | F37: 84 | G37: 4874212 | I37: =HYPERLINK("\\avrasya\THY_BSK_TEKNIK\MD_TEKNIK_ANLASMALAR_VE_ODEMELER\Teknik Envanter Takip Şefliği\IPC\A321\" &D37&"\"& A37 & ".png", "Resim için basınız") -> Resim için basınız
A38: BA16501-01 | B38: APU GENERATOR | D38: 24 | E38: IDG/GEN | F38: 176 | G38: 4795170.4 | I38: =HYPERLINK("\\avrasya\THY_BSK_TEKNIK\MD_TEKNIK_ANLASMALAR_VE_ODEMELER\Teknik Envanter Takip Şefliği\IPC\A321\" &D38&"\"& A38 & ".png", "Resim için basınız") -> Resim için basınız
A39: 745-3400-503 | B39: INLET COWL | D39: 71 | E39: COMPOSIT | F39: 37 | G39: 4772940.9 | I39: =HYPERLINK("\\avrasya\THY_BSK_TEKNIK\MD_TEKNIK_ANLASMALAR_VE_ODEMELER\Teknik Envanter Takip Şefliği\IPC\A321\" &D39&"\"& A39 & ".png", "Resim için basınız") -> Resim için basınız
A40: 745-0006-501 | B40: SLEEVE ASSY. LH | D40: 78 | E40: COMPOSIT | F40: 215 | G40: 4757446 | I40: =HYPERLINK("\\avrasya\THY_BSK_TEKNIK\MD_TEKNIK_ANLASMALAR_VE_ODEMELER\Teknik Envanter Takip Şefliği\IPC\A321\" &D40&"\"& A40 & ".png", "Resim için basınız") -> Resim için basınız
A41: RWA11-0008-00 | B41: GLOBAL SATELLITE ANTENNA ASSEMBLY (GSAA) | D41: 44 | E41: IFE | F41: 111 | G41: 4708414.4 | I41: =HYPERLINK("\\avrasya\THY_BSK_TEKNIK\MD_TEKNIK_ANLASMALAR_VE_ODEMELER\Teknik Envanter Takip Şefliği\IPC\A321\" &D41&"\"& A41 & ".png", "Resim için basınız") -> Resim için basınız
A42: Z014H010035C | B42: CIDS DIRECTOR | D42: 23 | E42: IFE | F42: 52 | G42: 4661174 | I42: =HYPERLINK("\\avrasya\THY_BSK_TEKNIK\MD_TEKNIK_ANLASMALAR_VE_ODEMELER\Teknik Envanter Takip Şefliği\IPC\A321\" &D42&"\"& A42 & ".png", "Resim için basınız") -> Resim için basınız
... A3060: 177778-901 | B3060: IN ARMREST VDU | D3060: 23 | E3060: IFE | F3060: 14 | G3060: 0 | I3060: =HYPERLINK("\\avrasya\THY_BSK_TEKNIK\MD_TEKNIK_ANLASMALAR_VE_ODEMELER\Teknik Envanter Takip Şefliği\IPC\A321\" &D3060&"\"& A3060 & ".png", "Resim için basınız") -> Resim için basınız
A3061: 201660002-025 | B3061: MLG SIDESTAY ASSY-R/H | C3061: ENİS | D3061: 32 | E3061: LDG | F3061: 15 | G3061: 0 | I3061: =HYPERLINK("\\avrasya\THY_BSK_TEKNIK\MD_TEKNIK_ANLASMALAR_VE_ODEMELER\Teknik Envanter Takip Şefliği\IPC\A321\" &D3061&"\"& A3061 & ".png", "Resim için basınız") -> Resim için basınız | J3061: resim girildi
...

Sheet A330
A1: PN | B1: PN DESC | C1: ilgili | D1: CHAPTER | E1: SUB CATEGORY | F1: QTY | G1: FA AMOUNT | H1: Fonksiyonu | I1: Görsel | J1: Resim Notu
A2: F5777210000600 | B2: 1 SPOILER LH | D2: 27 | E2: COMPOSIT | F2: 46 | G2: 0 | I2: =HYPERLINK("\\avrasya\THY_BSK_TEKNIK\MD_TEKNIK_ANLASMALAR_VE_ODEMELER\Teknik Envanter Takip Şefliği\IPC\A330\" &D2&"\"& A2 & ".png", "Resim için basınız") -> Resim için basınız
A3: F5777210000700 | B3: 1 SPOILER RH | D3: 27 | E3: COMPOSIT | F3: 46 | G3: 0 | I3: =HYPERLINK("\\avrasya\THY_BSK_TEKNIK\MD_TEKNIK_ANLASMALAR_VE_ODEMELER\Teknik Envanter Takip Şefliği\IPC\A330\" &D3&"\"& A3 & ".png", "Resim için basınız") -> Resim için basınız
A4: F5777100002900 | B4: 1 SPOILER RH | D4: 27 | E4: COMPOSIT | F4: 3 | G4: 18533.25 | I4: =HYPERLINK("\\avrasya\THY_BSK_TEKNIK\MD_TEKNIK_ANLASMALAR_VE_ODEMELER\Teknik Envanter Takip Şefliği\IPC\A330\" &D4&"\"& A4 & ".png", "Resim için basınız") -> Resim için basınız
A5: D23446200 | B5: LOOM, UPPER ELECTRICAL 1M | D5: 32 | E5: HARNESS | F5: 2 | G5: 0 | I5: =HYPERLINK("\\avrasya\THY_BSK_TEKNIK\MD_TEKNIK_ANLASMALAR_VE_ODEMELER\Teknik Envanter Takip Şefliği\IPC\A330\" &D5&"\"& A5 & ".png", "Resim için basınız") -> Resim için basınız
A6: F5777100103600 | B6: 2 SPOILER LH | D6: 27 | E6: COMPOSIT | F6: 3 | G6: 0 | I6: =HYPERLINK("\\avrasya\THY_BSK_TEKNIK\MD_TEKNIK_ANLASMALAR_VE_ODEMELER\Teknik Envanter Takip Şefliği\IPC\A330\" &D6&"\"& A6 & ".png", "Resim için basınız") -> Resim için basınız
A7: F5777220000600 | B7: 2 SPOILER LH | D7: 27 | E7: COMPOSIT | F7: 46 | G7: 0 | I7: =HYPERLINK("\\avrasya\THY_BSK_TEKNIK\MD_TEKNIK_ANLASMALAR_VE_ODEMELER\Teknik Envanter Takip Şefliği\IPC\A330\" &D7&"\"& A7 & ".png", "Resim için basınız") -> Resim için basınız
A8: F5777100103700 | B8: 2 SPOILER RH | D8: 27 | E8: COMPOSIT | F8: 4 | G8: 18667.5 | I8: =HYPERLINK("\\avrasya\THY_BSK_TEKNIK\MD_TEKNIK_ANLASMALAR_VE_ODEMELER\Teknik Envanter Takip Şefliği\IPC\A330\" &D8&"\"& A8 & ".png", "Resim için basınız") -> Resim için basınız
A9: F5777220000700 | B9: 2 SPOILER RH | D9: 27 | E9: COMPOSIT | F9: 46 | G9: 0 | I9: =HYPERLINK("\\avrasya\THY_BSK_TEKNIK\MD_TEKNIK_ANLASMALAR_VE_ODEMELER\Teknik Envanter Takip Şefliği\IPC\A330\" &D9&"\"& A9 & ".png", "Resim için basınız") -> Resim için basınız
A10: 86053-10 | B10: 2" WIDE CARGO LOCK ASSY | D10: 25 | E10: MECHANIC | F10: 17 | G10: 2274.47 | I10: =HYPERLINK("\\avrasya\THY_BSK_TEKNIK\MD_TEKNIK_ANLASMALAR_VE_ODEMELER\Teknik Envanter Takip Şefliği\IPC\A330\" &D10&"\"& A10 & ".png", "Resim için basınız") -> Resim için basınız
A11: 86053-11 | B11: 2" WIDE CARGO LOCK ASSY | D11: 25 | E11: MECHANIC | F11: 19 | G11: 75860 | I11: =HYPERLINK("\\avrasya\THY_BSK_TEKNIK\MD_TEKNIK_ANLASMALAR_VE_ODEMELER\Teknik Envanter Takip Şefliği\IPC\A330\" &D11&"\"& A11 & ".png", "Resim için basınız") -> Resim için basınız
A12: G5777230001200 | B12: 3 SPOILER LH | D12: 27 | E12: COMPOSIT | F12: 28 | G12: 0 | I12: =HYPERLINK("\\avrasya\THY_BSK_TEKNIK\MD_TEKNIK_ANLASMALAR_VE_ODEMELER\Teknik Envanter Takip Şefliği\IPC\A330\" &D12&"\"& A12 & ".png", "Resim için basınız") -> Resim için basınız
A13: F5777000001000 | B13: 3 SPOILER LH | D13: 27 | E13: COMPOSIT | F13: 3 | G13: 18533.25 | I13: =HYPERLINK("\\avrasya\THY_BSK_TEKNIK\MD_TEKNIK_ANLASMALAR_VE_ODEMELER\Teknik Envanter Takip Şefliği\IPC\A330\" &D13&"\"& A13 & ".png", "Resim için basınız") -> Resim için basınız
... A24: G5777240001100 | B24: 4 SPOILER RH | D24: 27 | E24: COMPOSIT | F24: 17 | G24: 0 | I24: =HYPERLINK("\\avrasya\THY_BSK_TEKNIK\MD_TEKNIK_ANLASMALAR_VE_ODEMELER\Teknik Envanter Takip Şefliği\IPC\A330\" &D24&"\"& A24 & ".png", "Resim için basınız") -> Resim için basınız
A25: RD-AA8110-02 | B25: 4G CELL MODEM | C25: TAHA | D25: 23 | E25: IFE | F25: 21 | G25: 106722.11 | H25: 4G mobil şebeke üzerinden veri iletişimi sağlayarak sistemin internet ile gerçek zamanlı bağlantı kurmasını sağlar | I25: =HYPERLINK("\\avrasya\THY_BSK_TEKNIK\MD_TEKNIK_ANLASMALAR_VE_ODEMELER\Teknik Envanter Takip Şefliği\IPC\A330\" &D25&"\"& A25 & ".png", "Resim için basınız") -> Resim için basınız | J25: Resim Girildi
A26: RD-AA8190-01 | B26: 4G ENHANCED CELL MODEM (4G ECM) | D26: 23 | E26: IFE | F26: 247 | G26: 898253.44 | I26: =HYPERLINK("\\avrasya\THY_BSK_TEKNIK\MD_TEKNIK_ANLASMALAR_VE_ODEMELER\Teknik Envanter Takip Şefliği\IPC\A330\" &D26&"\"& A26 & ".png", "Resim için basınız") -> Resim için basınız
A27: G5777250001200 | B27: 5 SPOILER LH | D27: 27 | E27: COMPOSIT | F27: 29 | G27: 0 | I27: =HYPERLINK("\\avrasya\THY_BSK_TEKNIK\MD_TEKNIK_ANLASMALAR_VE_ODEMELER\Teknik Envanter Takip Şefliği\IPC\A330\" &D27&"\"& A27 & ".png", "Resim için basınız") -> Resim için basınız
A28: F5777000201000 | B28: 5 SPOILER LH | D28: 27 | E28: COMPOSIT | F28: 3 | G28: 18533.25 | I28: =HYPERLINK("\\avrasya\THY_BSK_TEKNIK\MD_TEKNIK_ANLASMALAR_VE_ODEMELER\Teknik Envanter Takip Şefliği\IPC\A330\" &D28&"\"& A28 & ".png", "Resim için basınız") -> Resim için basınız
A29: G5777250001000 | B29: 5 SPOILER LH | D29: 27 | E29: COMPOSIT | F29: 17 | G29: 0 | I29: =HYPERLINK("\\avrasya\THY_BSK_TEKNIK\MD_TEKNIK_ANLASMALAR_VE_ODEMELER\Teknik Envanter Takip Şefliği\IPC\A330\" &D29&"\"& A29 & ".png", "Resim için basınız") -> Resim için basınız
A30: F5777000201100 | B30: 5 SPOILER RH | D30: 27 | E30: COMPOSIT | F30: 3 | G30: 18533.25 | I30: =HYPERLINK("\\avrasya\THY_BSK_TEKNIK\MD_TEKNIK_ANLASMALAR_VE_ODEMELER\Teknik Envanter Takip Şefliği\IPC\A330\" &D30&"\"& A30 & ".png", "Resim için basınız") -> Resim için basınız
A31: G5777250001100 | B31: 5 SPOILER RH | D31: 27 | E31: COMPOSIT | F31: 17 | G31: 0 | I31: =HYPERLINK("\\avrasya\THY_BSK_TEKNIK\MD_TEKNIK_ANLASMALAR_VE_ODEMELER\Teknik Envanter Takip Şefliği\IPC\A330\" &D31&"\"& A31 & ".png", "Resim için basınız") -> Resim için basınız
A32: F5777100203600 | B32: 6 SPOILER LH | D32: 27 | E32: COMPOSIT | F32: 3 | G32: 18533.25 | I32: =HYPERLINK("\\avrasya\THY_BSK_TEKNIK\MD_TEKNIK_ANLASMALAR_VE_ODEMELER\Teknik Envanter Takip Şefliği\IPC\A330\" &D32&"\"& A32 & ".png", "Resim için basınız") -> Resim için basınız
A33: F5777260000600 | B33: 6 SPOILER LH | D33: 27 | E33: COMPOSIT | F33: 45 | G33: 0 | I33: =HYPERLINK("\\avrasya\THY_BSK_TEKNIK\MD_TEKNIK_ANLASMALAR_VE_ODEMELER\Teknik Envanter Takip Şefliği\IPC\A330\" &D33&"\"& A33 & ".png", "Resim için basınız") -> Resim için basınız
A34: F5777260000700 | B34: 6 SPOILER RH | D34: 27 | E34: COMPOSIT | F34: 46 | G34: 0 | I34: =HYPERLINK("\\avrasya\THY_BSK_TEKNIK\MD_TEKNIK_ANLASMALAR_VE_ODEMELER\Teknik Envanter Takip Şefliği\IPC\A330\" &D34&"\"& A34 & ".png", "Resim için basınız") -> Resim için basınız
A35: F5777100203700 | B35: 6 SPOILER RH | D35: 27 | E35: COMPOSIT | F35: 3 | G35: 18533.25 | I35: =HYPERLINK("\\avrasya\THY_BSK_TEKNIK\MD_TEKNIK_ANLASMALAR_VE_ODEMELER\Teknik Envanter Takip Şefliği\IPC\A330\" &D35&"\"& A35 & ".png", "Resim için basınız") -> Resim için basınız
A36: 180770-201T1 | B36: 8.9" IN-ARM SVDU | D36: 23 | E36: IFE | F36: 5 | G36: 77042.31 | I36: =HYPERLINK("\\avrasya\THY_BSK_TEKNIK\MD_TEKNIK_ANLASMALAR_VE_ODEMELER\Teknik Envanter Takip Şefliği\IPC\A330\" &D36&"\"& A36 & ".png", "Resim için basınız") -> Resim için basınız
A37: 180771-201T1 | B37: 8.9" SEATBACK SVDU | D37: 23 | E37: IFE | F37: 13 | G37: 67453.69 | I37: =HYPERLINK("\\avrasya\THY_BSK_TEKNIK\MD_TEKNIK_ANLASMALAR_VE_ODEMELER\Teknik Envanter Takip Şefliği\IPC\A330\" &D37&"\"& A37 & ".png", "Resim için basınız") -> Resim için basınız
... A1023: 70N106-801 | B1023: ENGINE INLET COWL | D1023: 71 | E1023: COMPOSIT | F1023: 19 | G1023: 1506120 | I1023: =HYPERLINK("\\avrasya\THY_BSK_TEKNIK\MD_TEKNIK_ANLASMALAR_VE_ODEMELER\Teknik Envanter Takip Şefliği\IPC\A330\" &D1023&"\"& A1023 & ".png", "Resim için basınız") -> Resim için basınız
A1024: 4295121 | B1024: ENGINE SCAN LIGHT | C1024: TAHA | D1024: 33 | E1024: ELECTRIC | F1024: 1 | G1024: 3889.8 | H1024: Motorla ilgili belirli bilgileri tarayan veya gösterge değişimlerini işaret eden uyarı ışığıdır. | I1024: =HYPERLINK("\\avrasya\THY_BSK_TEKNIK\MD_TEKNIK_ANLASMALAR_VE_ODEMELER\Teknik Envanter Takip Şefliği\IPC\A330\" &D1024&"\"& A1024 & ".png", "Resim için basınız") -> Resim için basınız | J1024: Resim Girildi
A1025: 30-2671-7 | B1025: ENGINE SCAN LIGHT ASSY LH | D1025: 33 | E1025: ELECTRIC | F1025: 54 | G1025: 129935.82 | I1025: =HYPERLINK("\\avrasya\THY_BSK_TEKNIK\MD_TEKNIK_ANLASMALAR_VE_ODEMELER\Teknik Envanter Takip Şefliği\IPC\A330\" &D1025&"\"& A1025 & ".png", "Resim için basınız") -> Resim için basınız
A1026: 30-2671-8 | B1026: ENGINE SCAN LIGHT ASSY RH | D1026: 33 | E1026: ELECTRIC | F1026: 57 | G1026: 55379.78 | I1026: =HYPERLINK("\\avrasya\THY_BSK_TEKNIK\MD_TEKNIK_ANLASMALAR_VE_ODEMELER\Teknik Envanter Takip Şefliği\IPC\A330\" &D1026&"\"& A1026 & ".png", "Resim için basınız") -> Resim için basınız
A1027: 271-200-025-207 | B1027: ENGINE VIBRATION UNIT | D1027: 73 | E1027: ATE | F1027: 17 | G1027: 107623.9 | I1027: =HYPERLINK("\\avrasya\THY_BSK_TEKNIK\MD_TEKNIK_ANLASMALAR_VE_ODEMELER\Teknik Envanter Takip Şefliği\IPC\A330\" &D1027&"\"& A1027 & ".png", "Resim için basınız") -> Resim için basınız
A1028: 974976 | B1028: ENGINE_DRIVEN PUMP | D1028: 29 | E1028: HYDRAUL | F1028: 28 | G1028: 892782 | I1028: =HYPERLINK("\\avrasya\THY_BSK_TEKNIK\MD_TEKNIK_ANLASMALAR_VE_ODEMELER\Teknik Envanter Takip Şefliği\IPC\A330\" &D1028&"\"& A1028 & ".png", "Resim için basınız") -> Resim için basınız
A1029: 3022053-001 | B1029: ENGINE_DRIVEN PUMP | D1029: 29 | E1029: HYDRAUL | F1029: 241 | G1029: 892782 | I1029: =HYPERLINK("\\avrasya\THY_BSK_TEKNIK\MD_TEKNIK_ANLASMALAR_VE_ODEMELER\Teknik Envanter Takip Şefliği\IPC\A330\" &D1029&"\"& A1029 & ".png", "Resim için basınız") -> Resim için basınız
A1030: 974800 | B1030: ENGINE_DRIVEN PUMP | D1030: 29 | E1030: HYDRAUL | F1030: 11 | G1030: 300916.82 | I1030: =HYPERLINK("\\avrasya\THY_BSK_TEKNIK\MD_TEKNIK_ANLASMALAR_VE_ODEMELER\Teknik Envanter Takip Şefliği\IPC\A330\" &D1030&"\"& A1030 & ".png", "Resim için basınız") -> Resim için basınız
A1031: 3022151-000 | B1031: ENGINE_DRIVEN PUMP | D1031: 29 | E1031: HYDRAUL | F1031: 9 | G1031: 810298.96 | I1031: =HYPERLINK("\\avrasya\THY_BSK_TEKNIK\MD_TEKNIK_ANLASMALAR_VE_ODEMELER\Teknik Envanter Takip Şefliği\IPC\A330\" &D1031&"\"& A1031 & ".png", "Resim için basınız") -> Resim için basınız
A1032: RD-AA5007-13 | B1032: ENH. VIDEO SYS CONTR UNIT | D1032: 23 | E1032: IFE | F1032: 5 | G1032: 17279.03 | I1032: =HYPERLINK("\\avrasya\THY_BSK_TEKNIK\MD_TEKNIK_ANLASMALAR_VE_ODEMELER\Teknik Envanter Takip Şefliği\IPC\A330\" &D1032&"\"& A1032 & ".png", "Resim için basınız") -> Resim için basınız
A1033: RD-AA1008-01 | B1033: ENHAN. PES CONTROLLER II | D1033: 23 | E1033: IFE | F1033: 7 | G1033: 42474.05 | I1033: =HYPERLINK("\\avrasya\THY_BSK_TEKNIK\MD_TEKNIK_ANLASMALAR_VE_ODEMELER\Teknik Envanter Takip Şefliği\IPC\A330\" &D1033&"\"& A1033 & ".png", "Resim için basınız") -> Resim için basınız
A1034: 69000942-151 | B1034: ENHANCED EGPWC | D1034: 34 | E1034: ATE | F1034: 82 | G1034: 89874.3 | I1034: =HYPERLINK("\\avrasya\THY_BSK_TEKNIK\MD_TEKNIK_ANLASMALAR_VE_ODEMELER\Teknik Envanter Takip Şefliği\IPC\A330\" &D1034&"\"& A1034 & ".png", "Resim için basınız") -> Resim için basınız
A1035: C19755BA01 | B1035: ENHANCED LIQ.CRYS.DISP.UN | D1035: 31 | E1035: ATE | F1035: 1088 | G1035: 5483816 | I1035: =HYPERLINK("\\avrasya\THY_BSK_TEKNIK\MD_TEKNIK_ANLASMALAR_VE_ODEMELER\Teknik Envanter Takip Şefliği\IPC\A330\" &D1035&"\"& A1035 & ".png", "Resim için basınız") -> Resim için basınız
...

Sheet A350
A1: PN | B1: PN DESC | C1: ilgili | D1: CHAPTER | E1: SUB CATEGORY | F1: QTY | G1: FA AMOUNT | H1: Fonksiyonu | I1: Görsel | J1: Resim Notu
